Workbook
Name FCARN: Listas!$M$4:$M$9
Name DEBILIDADOFORTALEZA: #REF!
Name FORMACION: #REF!
Name FCHYEuno: #REF!
Name Doctorado: #REF!
Name Maestria: #REF!
Name FCARNcuatro: #REF!
Name DEBILIDADOFORTALEZA: #REF!
Name FACULTADES: Listas!$B$4:$B$8
Name Pregrado: #REF!
Name FCE: Listas!$J$4:$J$9
Name FCEdos: #REF!
Name FCHYEtres: #REF!
Name Especializacion: #REF!
Name FCHYE: Listas!$Q$4:$Q$8
Name FCS: Listas!$D$4:$D$9
Name FCHYEdos: #REF!
Name FCARNuno: #REF!
Name FCBIuno: #REF!
Name DEBILIDADOFORTALEZA: #REF!
Name FCARNtres: #REF!
Name FCEtres: #REF!
Name FCARNdos: #REF!
Name FCStres: #REF!
Name FCBI: Listas!$G$4:$G$9
Name FCBItres: #REF!
Name FCSdos: #REF!
Name DEBILIDADOFORTALEZA: #REF!
Name FCSuno: #REF!
Name FCBIdos: #REF!
Name FCEuno: #REF!

Sheet TMI
A2: =IF('Plan mejoramiento'!B5="Institucional","TABLERO DE MANDO","TABLERO DE MANDO PLAN DE MEJORAMIENTO") -> TABLERO DE MANDO PLAN DE MEJORAMIENTO
A3: =IF('Plan mejoramiento'!B5="Institucional","PLAN DE MEJORAMIENTO INSTITUCIONAL",CONCATENATE('Plan mejoramiento'!D5," ",'Plan mejoramiento'!E5)) -> Programa: Ingeniería Electrónica
A5: ='Plan mejoramiento'!C8 -> Descripción de la oportunidad de mejora | B5: ='Plan mejoramiento'!D8 -> Nombre del proyecto | C5: Avance de acuerdo a las metas programadas cada año | K5: Avance total del Proyecto
C6: Año 1 | D6: Año 2 | E6: Año 3 | F6: Año 4 | G6: Año 5 | H6: Año 6 | I6: Año 7 | J6: Año 8
A7: ='Plan mejoramiento'!C10 -> Continuar con estrategias para lograr que los resultados de la prueba Saber Pro sean mayores en todas las competencias ai promedio obtenido por los estudiantes del grupo de referencia NBC. | B7: ='Plan mejoramiento'!G10 -> Meta 1. Mantener cinco (5) puntos por encima de los resultados de la prueba Saber Pro del grupo de referencia | K7: =IFERROR(AVERAGE(C7:J7),"")
A8: ='Plan mejoramiento'!C11 -> Mantener la participación en las actividades de Bienestar de un porcentaje significativo de estudiantes del Programa en cada periodo, dada la importancia declarada por la institución, en el desarrollo integral y en la permanencia. | B8: ='Plan mejoramiento'!G11 -> Meta 2a.2b, 2c Incrementar al 60% la participación de la comunidad del programa en actividades de bienestar institucional | K8: =IFERROR(AVERAGE(C8:J8),"")
A9: ='Plan mejoramiento'!C12 -> Bajo porcentaje de profesores y administrativos en actividades de Bienestar | K9: =IFERROR(AVERAGE(C9:J9),"")
K10: =IFERROR(AVERAGE(C10:J10),"")
A11: ='Plan mejoramiento'!C14 -> El número de profesores no es suficiente para las necesidades del programa en relación con el número de estudiantes. | B11: ='Plan mejoramiento'!G14 -> Meta 3. Desarrollar una (1) convocatoria de planta docente | K11: =IFERROR(AVERAGE(C11:J11),"")
A12: ='Plan mejoramiento'!C15 -> Los tiempos de dedicación a las funciones misionales no cumplen con lo establecido en los indicadores del programa. | B12: ='Plan mejoramiento'!G15 -> Meta 4. Incrementar al 25% la asignación de tiempos de los docentes TC a la investigación | K12: =IFERROR(AVERAGE(C12:J12),"")
B13: ='Plan mejoramiento'!G16 -> Meta 5. Incrementar al 20% la asignación de tiempos de los docentes TC a la Proyección Social | K13: =IFERROR(AVERAGE(C13:J13),"")
A14: ='Plan mejoramiento'!C17 -> Continuar con estrategias para aumentar el material de apoyo docente, su aplicación, y difusión. | B14: ='Plan mejoramiento'!G17 -> Meta 6. Desarrollar una (1) estrategia anual para fomentar la productividad y el material de apoyo docente | K14: =IFERROR(AVERAGE(C14:J14),"")
A15: ='Plan mejoramiento'!C18 -> El número de productos derivados de la participación de profesores, estudiantes y directivos del programa en redes u organismos nacionales e internacionales es bajo. | B15: ='Plan mejoramiento'!G18 -> Meta 7. Incrementar al 30% la participación de los docentes en redes u organismos nacionales e internacionales para generar productos | K15: =IFERROR(AVERAGE(C15:J15),"")
B16: ='Plan mejoramiento'!G19 -> Meta 8. Desarrollar un (1) producto bienalmente como resultado de la articulación de redes académicas | K16: =IFERROR(AVERAGE(C16:J16),"")
A17: ='Plan mejoramiento'!C20 -> Continuar promoviendo la movilidad entrante nacional e internacional y la saliente nacional | B17: ='Plan mejoramiento'!G20 -> Meta 9. Realizar la movilidad de un (1) estudiante extranjero bienalmente | K17: =IFERROR(AVERAGE(C17:J17),"")
A18: ='Plan mejoramiento'!C21 -> Aumentar la movilidad saliente de estudiantes del Programa en distintas modalidades. Aunque el Programa argumenta la reducción en este indicador, en la pandemia y el paro, es posible complementar estos resultados, estableciendo otras actividades en distintas modalidades con efectos en la visibilidad y la cooperación nacional e internacional. | B18: ='Plan mejoramiento'!G21 -> Meta 10. Lograr que el 20% de estudiantes a partir del V semestre realicen movilidad saliente nacional o internacional anualmente | K18: =IFERROR(AVERAGE(C18:J18),"")
A19: ='Plan mejoramiento'!C22 -> Persistir en acciones que permitan de manera efectiva continuar disminuyendo la deserción en el Programa. La tasa de deserción anual para 3 periodos entre 2019 y 2021 es superior al promedio nacional para nivel de formación. | B19: ='Plan mejoramiento'!G22 -> Meta 11. Mantener un (1) digito la tasa deserción del programa | K19: =IFERROR(AVERAGE(C19:J19),"")
A20: ='Plan mejoramiento'!C23 -> Continuar con la estrategia para lograr la graduación en el tiempo aprobado en el registro calificado. La tasa acumulada de graduación del Programa al semestre 13 es del 23.57% inferior al promedio nacional para el profesional universitario. Aunque es mejor con relación al proceso anterior de acreditación, aún hay una Oportunidad de mejora significativa en el comparativo nacional con el promedio del nivel de formación. | B20: ='Plan mejoramiento'!G23 -> Meta 12. Mantener en 12,5 de semestres para la graduación | K20: =IFERROR(AVERAGE(C20:J20),"")
A21: ='Plan mejoramiento'!C24 -> Continuar con estrategias y apoyos para mejorar la categoría de los grupos de investigación y el reconocimiento de profesores como investigadores. | B21: ='Plan mejoramiento'!G24 -> Meta 13. Lograr que un (1) grupos de investigación suba de categoría | K21: =IFERROR(AVERAGE(C21:J21),"")
A22: ='Plan mejoramiento'!C25 -> Se requiere incrementar el número de registros de egresados en la base de datos | B22: ='Plan mejoramiento'!G25 -> Meta 14. Aumentar al 45% los registros actualizados de los egresados en la base de datos del Programa | K22: =IFERROR(AVERAGE(C22:J22),"")
A23: ='Plan mejoramiento'!C26 -> Continuar robusteciendo la infraestructura de laboratorios y equipos disponibles para el Programa en las distintas líneas de profundización, tanto para la docencia, coma para la investigación, y cumplir con el plan de mantenimiento y calibración de equipos de laboratorios de manera permanente. | B23: ='Plan mejoramiento'!G26 -> Meta 15. Construir un (1) complejo de laboratorios | K23: =IFERROR(AVERAGE(C23:J23),"")
B24: ='Plan mejoramiento'!G27 -> Meta 16. Ejecutar el 100% del plan de adquisición de equipos de medios educativos para los laboratorios del Sistema de Gestión de Laboratorios. | K24: =IFERROR(AVERAGE(C24:J24),"")
A25: ='Plan mejoramiento'!C28 -> Se requiere fortalecer el seguimiento de la medición de impacto que evidencie el desarrollo de las funciones misionales | B25: ='Plan mejoramiento'!G28 -> Meta 17. Obtener el nivel de cumplimiento mayor o igual al 80% en la medición del impacto | K25: =IFERROR(AVERAGE(C25:J25),"")
A26: Nivel de ejecución del plan de mejoramiento

Sheet Plan mejoramiento
B1: PROCESO DE GESTIÓN DE LA CALIDAD
B2: PLAN DE MEJORAMIENTO 2024-2- 2030
B3: Código: FO-GCL-20 | H3: Versión: 03 | J3: Fecha de aprobación: 23/07/2024 | U3: Página: 1 de 2
A5: Tipo de plan de mejoramiento: | B5: De programa | D5: =IF(B5=Listas!A5,"Programa:","") -> Programa: | E5: Ingeniería Electrónica | H5: Proceso: | I5: Autoevaluación con fines de calidad 2020-2023-1 | J5: Alta calidad: | L5: Reacreditación
A6: =IF(B5=Listas!A5,"Facultad:","") -> Facultad: | B6: Facultad de Ciencias Básicas e Ingeniería | D6: =IF(B5=Listas!A5,"Nivel de formación:","") -> Nivel de formación: | E6: Pregrado | H6: Fecha de suscripción: | I6: 19 de Junio de 2024 | J6: =IF(B5=Listas!A5,"Director de programa:","") -> Director de programa: | L6: Héctor Iván Reyes Moncayo
A8: Factor / Condición (Aspecto) | B8: Origen de la oportunidad de mejora | C8: Descripción de la oportunidad de mejora | D8: Nombre del proyecto | E8: Peso del proyecto | F8: Tipo de meta | G8: Meta de la oportunidad de mejora | H8: Indicador de la meta | I8: Actividades de la Meta | J8: Recursos para su financiación | K8: Línea base de la Meta | L8: Programación de la meta | U8: Responsable
L9: 44958 | M9: Año 1 2024 | N9: Año 2 2025 | O9: Año 3 2026 | P9: Año 4 2027 | Q9: Año 5 2028 | R9: Año 6 2029 | S9: Año 7 2030 | T9: Total
A10: Factor 2. Estudiantes | B10: Determinación del CNA | C10: Continuar con estrategias para lograr que los resultados de la prueba Saber Pro sean mayores en todas las competencias ai promedio obtenido por los estudiantes del grupo de referencia NBC. | D10: Apoyo a los procesos de aseguramiento de la calidad académica en la Universidad de los Llanos. | E10: =100%/17 -> 0.058823529 | F10: Institucional / Programa | G10: Meta 1. Mantener cinco (5) puntos por encima de los resultados de la prueba Saber Pro del grupo de referencia | H10: No. de puntos por encima del grupo de referencia | I10: 1. Hacer seguimiento a la participación de los estudiantes en las estrategias institucionales 2. Hacer seguimiento a las estrategias implementadas por el programa en cada uno de los cursos 3. Presentar un informe de seguimiento anual al comité de programa | J10: Recursos de Funcionamiento e inversión | K10: 165 Programa 153 Grupo de referencia | L10: 165 | M10: 165 | N10: 165 | O10: 165 | P10: 165 | Q10: 165 | R10: 165 | S10: 165 | T10: 165 | U10: Dirección General de Currículo Comité de Programa Profesores del programa
A11: Factor 9. Bienestar de la Comunidad Académica del Programa | B11: Determinación del CNA | C11: Mantener la participación en las actividades de Bienestar de un porcentaje significativo de estudiantes del Programa en cada periodo, dada la importancia declarada por la institución, en el desarrollo integral y en la permanencia. | D11: Fortalecimiento y desarrollo de estrategias y acciones de bienestar en el marco del desarrollo humano en pro de los integrantes de la comunidad universitaria de los Llanos | E11: =100%/17 -> 0.058823529 | F11: Institucional / Programa | G11: Meta 2a.2b, 2c Incrementar al 60% la participación de la comunidad del programa en actividades de bienestar institucional | H11: % estudiantes participando en Bienestar Institucional | I11: 1.Realizar convocatorias para vincular estudiantes, profesores y administrativos en a actividades de bienestar. 2. Ejecutar el portafolio de servicios de Bienestar 3. Informe de seguimiento sobre la participación de estudiantes, profesores y administrativos en actividades de bienestar institucional. | J11: Recursos de Funcionamiento e inversión | K11: 0.501 | L11: 0.501 | M11: 0.6 | N11: 0.6 | O11: 0.6 | P11: 0.6 | Q11: 0.6 | R11: 0.6 | S11: 0.6 | T11: 0.6 | U11: Bienestar Institucional Consejo de FCBI Comité de Programa
C12: Bajo porcentaje de profesores y administrativos en actividades de Bienestar | H12: % Profesores participando en Bienestar Institucional | J12: Recursos de Funcionamiento e inversión | K12: 0.14 | L12: 0.14 | M12: 0.6 | N12: 0.6 | O12: 0.6 | P12: 0.6 | Q12: 0.6 | R12: 0.6 | S12: 0.6 | T12: 0.6
H13: % Administrativos participando en Bienestar Institucional | J13: Recursos de Funcionamiento e inversión | K13: 0.08 | L13: 0.08 | M13: 0.6 | N13: 0.6 | O13: 0.6 | P13: 0.6 | Q13: 0.6 | R13: 0.6 | S13: 0.6 | T13: 0.6
A14: Factor 3. Profesores | B14: Proceso de autoevaluación | C14: El número de profesores no es suficiente para las necesidades del programa en relación con el número de estudiantes. | D14: Apoyo a la formación de alto nivel y fortalecimiento de las competencias docentes en la Universidad de los Llanos | E14: =100%/17 -> 0.058823529 | F14: Institucional | G14: Meta 3. Desarrollar una (1) convocatoria de planta docente | H14: No. de convocatorias desarrolladas | I14: 1. Identificar los perfiles. 2. Desarrollar las etapas del concurso de acuerdo con la normatividad aplicable 3. Formalizar nombramiento de los docentes ganadores del concurso | J14: Recursos contemplado en el Plan de Mejoramiento Institucional 2022-2028 | K14: 1 | L14: 0 | M14: 0 | N14: 0 | O14: 1 | P14: 0 | Q14: 0 | R14: 0 | S14: 0 | T14: =SUM(N14:O14) -> 1 | U14: Consejo Superior Consejo Académico Consejo de Facultad. Comité de programa
B15: Proceso de autoevaluación | C15: Los tiempos de dedicación a las funciones misionales no cumplen con lo establecido en los indicadores del programa. | D15: Generar capacidades en innovación, desarrollo tecnológico y creación para la generación, uso y transferencia del conocimiento en la Universidad de los Llanos | E15: =100%/17 -> 0.058823529 | F15: Institucional | G15: Meta 4. Incrementar al 25% la asignación de tiempos de los docentes TC a la investigación | H15: % de asignación de horas a la función misional de investigación | I15: 1. Realizar las convocatorias de proyectos de investigación y de proyección social. 2. Presentar y avalar los proyectos de investigación y proyección social. 3. Asignar a docentes los tiempos destinados a las funciones misionales de acuerdo con indicadores 4. Revisar indicadores y la tipificación de las asignaciones | J15: Recursos de Funcionamiento e inversión | K15: 0.07 | L15: 0.07 | M15: 0.1 | N15: 0.15 | O15: 0.2 | P15: 0.25 | Q15: 0.25 | R15: 0.25 | S15: 0.25 | T15: 0.25 | U15: Consejo académico Consejo de Facultad Comité de Programa Comité de Escuela Ingeniería Departamento de Básicas
D16: Escenarios de extensión, apropiación y responsabilidad social de la Universidad de los Llanos | E16: =100%/17 -> 0.058823529 | G16: Meta 5. Incrementar al 20% la asignación de tiempos de los docentes TC a la Proyección Social | H16: % de asignación de horas a la función de proyección social | J16: Recursos de Funcionamiento e inversión | K16: 0.04 | L16: 0.04 | M16: 0.08 | N16: 0.12 | O16: 0.16 | P16: 0.2 | Q16: 0.2 | R16: 0.2 | S16: 0.2 | T16: 0.2
B17: Determinación del CNA | C17: Continuar con estrategias para aumentar el material de apoyo docente, su aplicación, y difusión. | D17: Generar capacidades en innovación, desarrollo tecnológico y creación para la generación, uso y transferencia del conocimiento en la Universidad de los Llanos | E17: =100%/17 -> 0.058823529 | F17: Programa | G17: Meta 6. Desarrollar una (1) estrategia anual para fomentar la productividad y el material de apoyo docente | H17: No. de estrategias desarrolladas anualmente | I17: 1. Revisar la conceptualización y los criterios del material de apoyo docente 2. Diseñar y desarrollar el repositorio de material de apoyo docente 3. Análisis de la evaluación del material de apoyo docente 4. Presentar informe al comité de programa | J17: Recursos de Inversión y Funcionamiento | K17: 1 | L17: 1 | M17: 1 | N17: 1 | O17: 1 | P17: 1 | Q17: 1 | R17: 1 | S17: 1 | T17: 1 | U17: Comité de Programa Profesores
A18: Factor 5 - Visibilidad nacional e internacional | B18: Proceso de autoevaluación | C18: El número de productos derivados de la participación de profesores, estudiantes y directivos del programa en redes u organismos nacionales e internacionales es bajo. | D18: Posicionamiento y visibilidad de la Universidad de los Llanos en dinámicas mundiales a través de su relacionamiento con actores nacionales e internacionales | E18: =100%/17 -> 0.058823529 | F18: Institucional / Programa | G18: Meta 7. Incrementar al 30% la participación de los docentes en redes u organismos nacionales e internacionales para generar productos | H18: % de docentes que participan en redes u organismos académicos con productos o resultados | I18: 1, Generar inscripciones y participaciones en redes académicas u organismos nacionales e internacionales | J18: Recursos de Funcionamiento contemplados en el Plan de Mejoramiento Institucional 2022-2028 | K18: =4/29 -> 0.13793103 | L18: 0.1379 | M18: 0.2 | N18: 0.22 | O18: 0.25 | P18: 0.3 | Q18: 0.3 | R18: 0.3 | S18: 0.3 | T18: 0.3 | U18: Vicerrectoría Académica Vicerrectoría de Recursos Dirección General de Investigaciones. Dirección General de Proyección Social. Comité de programa
E19: =100%/17 -> 0.058823529 | G19: Meta 8. Desarrollar un (1) producto bienalmente como resultado de la articulación de redes académicas | H19: No. producto desarrollado | K19: 0 | L19: 0 | M19: 1 | N19: 0 | O19: 1 | P19: 0 | Q19: 1 | R19: 0 | S19: 0 | T19: 1
B20: Determinación del CNA | C20: Continuar promoviendo la movilidad entrante nacional e internacional y la saliente nacional | D20: Posicionamiento y visibilidad de la Universidad de los Llanos en dinámicas mundiales a través de su relacionamiento con actores nacionales e internacionales | E20: =100%/17 -> 0.058823529 | F20: Institucional / Programa | G20: Meta 9. Realizar la movilidad de un (1) estudiante extranjero bienalmente | H20: No. de estudiantes visitantes del programa. | I20: 1. Actualizar y mantener los convenios internacionales para incrementar el número de estudiantes visitantes | J20: Recurso por inversión y/o Externos | K20: 1 | L20: 0 | M20: 1 | N20: 0 | O20: 1 | P20: 0 | Q20: 1 | R20: 0 | S20: 0 | T20: 1 | U20: Oficina de Relaciones Interinstitucionales OIRI. Consejo de FCBI Comité de programa.
B21: Determinación del CNA | C21: Aumentar la movilidad saliente de estudiantes del Programa en distintas modalidades. Aunque el Programa argumenta la reducción en este indicador, en la pandemia y el paro, es posible complementar estos resultados, estableciendo otras actividades en distintas modalidades con efectos en la visibilidad y la cooperación nacional e internacional. | D21: Posicionamiento y visibilidad de la Universidad de los Llanos en dinámicas mundiales a través de su relacionamiento con actores nacionales e internacionales | E21: =100%/17 -> 0.058823529 | F21: Institucional / Programa | G21: Meta 10. Lograr que el 20% de estudiantes a partir del V semestre realicen movilidad saliente nacional o internacional anualmente | H21: % de estudiantes beneficiarios de movilidad saliente | I21: 1. Socializar las convocatorias de movilidad nacional e internacional a los estudiantes 2. Implementar actividades en distintas modalidades que permitan aumentar la movilidad estudiantil 3. Postular estudiantes para movilidad 4. Informe de seguimiento a la movilidad de los estudiantes | J21: Recurso por inversión y/o Externos | K21: =16/103 -> 0.15533981 | L21: =K21 -> 0.15533981 | M21: 0.16 | N21: 0.17 | O21: 0.18 | P21: 0.19 | Q21: 0.2 | R21: 0.2 | S21: 0.2 | T21: 0.2 | U21: Oficina de Relaciones Interinstitucionales OIRI Consejo de FCBI Comité de Programa
A22: Factor 6 Permanencia y graduación | B22: Determinación del CNA | C22: Persistir en acciones que permitan de manera efectiva continuar disminuyendo la deserción en el Programa. La tasa de deserción anual para 3 periodos entre 2019 y 2021 es superior al promedio nacional para nivel de formación. | D22: Fortalecimiento y desarrollo de estrategias y acciones de bienestar en el marco del desarrollo humano en pro de los integrantes de la comunidad universitaria de los Llanos | E22: =100%/17 -> 0.058823529 | F22: Institucional / Programa | G22: Meta 11. Mantener un (1) digito la tasa deserción del programa | H22: % de la tasa de deserción | I22: 1. Socializar las estrategias del sistema de alertas tempranas 2. Articular a los cursos las estrategias para superar el bajo rendimiento de los estudiantes 3. Informe semestral sobre | J22: Recursos de Funcionamiento e inversión | K22: 6,25% lel programa 11,03% es la media nacional | L22: 0.056 | M22: 0.056 | N22: 0.05 | O22: 0.045 | P22: 0.04 | Q22: 0.04 | R22: 0.04 | S22: 0.04 | T22: 0.04 | U22: PREU Comité de Programa Profsores Estudiantes
B23: Determinación del CNA | C23: Continuar con la estrategia para lograr la graduación en el tiempo aprobado en el registro calificado. La tasa acumulada de graduación del Programa al semestre 13 es del 23.57% inferior al promedio nacional para el profesional universitario. Aunque es mejor con relación al proceso anterior de acreditación, aún hay una Oportunidad de mejora significativa en el comparativo nacional con el promedio del nivel de formación. | D23: Fortalecimiento y desarrollo de estrategias y acciones de bienestar en el marco del desarrollo humano en pro de los integrantes de la comunidad universitaria de los Llanos | E23: =100%/17 -> 0.058823529 | F23: Institucional / Programa | G23: Meta 12. Mantener en 12,5 de semestres para la graduación | H23: No. de semestres de graduación de los estudiantes | I23: 1. Revisar las características del curso de proyecto de grado 2. Hacer seguimiento al curso proyecto de grado y opciones de grado 2. Presentar un informe de seguimiento al comité | J23: Recursos de Funcionamiento | K23: 12,5 semestres | L23: 12.5 | M23: 12.5 | N23: 12.5 | O23: 12.5 | P23: 12.5 | Q23: 12.5 | R23: 12.5 | S23: 12.5 | T23: 12.5 | U23: Comité de programa Profesores
A24: Factor 8. Aportes a la investigación | B24: Determinación del CNA | C24: Continuar con estrategias y apoyos para mejorar la categoría de los grupos de investigación y el reconocimiento de profesores como investigadores. | D24: Generar capacidades en innovación, desarrollo tecnológico y creación para la generación, uso y transferencia del conocimiento en la Universidad de los Llanos | E24: =100%/17 -> 0.058823529 | F24: Institucional | G24: Meta 13. Lograr que un (1) grupos de investigación suba de categoría | H24: N° de grupos que subieron de categoría | I24: 1. Implementar estrategia para el fortalecimiento y categorización de los grupos de investigación participantes en Convocatorias de Minciencias, | J24: Recursos de Funcionamiento e inversión | K24: 1 grupo en B y 4 en C | L24: 2 | M24: 2 | N24: 1 | O24: 1 | P24: 1 | Q24: 1 | R24: 1 | S24: 1 | T24: 1 | U24: Dirección General de Investigación
A25: Factor 9 - Impacto de los egresados en el medio | B25: Proceso de autoevaluación | C25: Se requiere incrementar el número de registros de egresados en la base de datos | D25: Escenarios de extensión, apropiación y responsabilidad social de la Universidad de los Llanos | E25: =100%/17 -> 0.058823529 | F25: Institucional | G25: Meta 14. Aumentar al 45% los registros actualizados de los egresados en la base de datos del Programa | H25: % de nuevos registros en la base de datos | I25: 1. Desarrollar actividades académicas que involucren a los egresados 2. Actualizar la base de datos permanentemente 3. Informe anual sobre seguimientos a egresados | J25: Recursos de Funcionamiento | K25: 0.35 | L25: 0.35 | M25: 0.4 | N25: 0.4 | O25: 0.45 | P25: 0.45 | Q25: 0.45 | R25: 0.45 | S25: 0.45 | T25: 0.45 | U25: Programa de Egresados Centro de proyección social FCBI
A26: Factor 10 - Recursos físicos y financieros | B26: Determinación del CNA | C26: Continuar robusteciendo la infraestructura de laboratorios y equipos disponibles para el Programa en las distintas líneas de profundización, tanto para la docencia, coma para la investigación, y cumplir con el plan de mantenimiento y calibración de equipos de laboratorios de manera permanente. | D26: Fortalecimiento del sistema de laboratorios como apoyo al desarrollo de las funciones misionales de la universidad de los llanos | E26: =100%/17 -> 0.058823529 | F26: Institucional | G26: Meta 15. Construir un (1) complejo de laboratorios | H26: N° de complejos de laboratorios construidos | I26: 1.Determinar las necesidades de las unidades académicas 2.Formular el proyecto de consultoría para diseños y estudios 3.Presentar el proyecto de construcción ante SGR 4.Ejecutar el proyecto de complejo de laboratorios | J26: Recursos de inversión contemplados en el Plan de Mejoramiento Institucional 2022-2028 | K26: 0 | L26: 0 | M26: 0 | N26: 0 | O26: 0 | P26: 1 | Q26: 0 | R26: 0 | S26: 0 | T26: 1 | U26: Coordinación de laboratorios Vicerrectoría de Recursos Universitarios
D27: Dotación de equipos para los laboratorios básicos y especializados de la Universidad de los Llanos | E27: =100%/17 -> 0.058823529 | G27: Meta 16. Ejecutar el 100% del plan de adquisición de equipos de medios educativos para los laboratorios del Sistema de Gestión de Laboratorios. | H27: % de ejecución del plan de adquisición de equipos de laboratorios | I27: 1. Identificar las necesidades de los laboratorios en equipos y gestionar los recursos pertinentes 2. Formular los proyectos de inversión para adquisición de equipos de laboratorio acorde al plan de medios educativos. 3. Ejecutar los proyectos de inversión | J27: Recursos de Funcionamiento contemplados en el Plan de Mejoramiento Institucional 2022-2028 | K27: 0 | L27: 0.28 | M27: 0.4 | N27: 0.53 | O27: 0.65 | P27: 0.84 | Q27: =P27+ 16.39% -> 1.0039 | R27: 1 | S27: 1 | T27: =Q27 -> 1.0039
A28: Todos los factores | B28: Proceso de autoevaluación | C28: Se requiere fortalecer el seguimiento de la medición de impacto que evidencie el desarrollo de las funciones misionales | D28: Escenarios de extensión, apropiación y responsabilidad social de la Universidad de los Llanos | E28: =100%/17 -> 0.058823529 | F28: Programa | G28: Meta 17. Obtener el nivel de cumplimiento mayor o igual al 80% en la medición del impacto | H28: % de medición de impacto | I28: 1. Seguimiento y evaluación a las variables del modelo de impacto 2. Informe sobre resultados de la medición de impacto | J28: Recursos de Funcionamiento | K28: 0.6 | L28: 0.6 | M28: 0.7 | N28: 0.8 | O28: 0.8 | P28: 0.8 | Q28: 0.8 | R28: 0.8 | S28: 0.8 | T28: 0.8 | U28: Comité de Programa Director de Programa Comité de Escuela
A31: Elaborado: | B31: Director de Programa de Ing. Electrónica | D31: Aprobado: | E31: Comité de Programa Académico | H31: Aprobado: | I31: Consejo de Facultad de Ciencias Básicas e Ingeniería | J31: Aprobado: | K31: Consejo Académico
A32: Firma: | D32: Firma: | H32: Firma: | J32: Firma: | K32: =IF(C6="Institucional","Consejo Superior",IF(C6="De programa","Consejo de Facultad",""))
A33: Nombre: | B33: Héctor Iván Reyes Moncayo | D33: Nombre: | E33: Héctor Iván Reyes Moncayo | H33: Nombre: | I33: Elvis Miguel Pérez Rodríguez | J33: Nombre: | K33: Omaira Elizabeth González Giraldo
A34: Cargo: | B34: Director de Programa | D34: Cargo: | E34: Director de Programa | H34: Cargo: | I34: Decano de la Facultad | J34: Cargo: | K34: Secretaria General AD-HOC
A35: Acta No. | B35: 17 de 2024 | D35: Acta No. | E35: 17 de 2024 | H35: Acta No. | I35: 24 de 2024 | J35: Acta No. | K35: 27 de 2024
A36: Fecha: | B36: 19 de Junio de 2024 | D36: Fecha: | E36: 19 de Junio de 2024 | H36: Fecha: | I36: 20 de Junio de 2024 | J36: Fecha: | K36: 23 de Julio de 2024
A38: Visto Bueno Acreditación Nombre: Ana Bety Vacca Casanova Cargo: Secretaria Técnica de Acreditación Fecha: 23/07/2024 | D38: Visto Bueno Planeación Nombre: María Paula Estupiñán Tiuso Cargo: Asesora Oficina de Planeación Fecha: 23/07/2024

Sheet 2024-2
B1: PROCESO DE GESTIÓN DE LA CALIDAD
B2: PLAN DE MEJORAMIENTO DE PROCESOS DE AUTOEVALUACIÓN
B3: Código: FO-GCL-20 | D3: Versión: 03 | E3: Fecha de aprobación: 14/06/2022 | G3: Página: 2 de 4
A5: Tipo de plan de mejoramiento: | B5: =IF('Plan mejoramiento'!B5="","",'Plan mejoramiento'!B5) -> De programa | D5: =IF('Plan mejoramiento'!E5="","",CONCATENATE('Plan mejoramiento'!D5," ",'Plan mejoramiento'!E5)) -> Programa: Ingeniería Electrónica
A6: ='Plan mejoramiento'!A6 -> Facultad: | B6: ='Plan mejoramiento'!B6 -> Facultad de Ciencias Básicas e Ingeniería | D6: =IF('Plan mejoramiento'!J6="","",CONCATENATE('Plan mejoramiento'!J6," ",#REF!)) -> #REF!
A8: ='Plan mejoramiento'!C8 -> Descripción de la oportunidad de mejora | B8: ='Plan mejoramiento'!G8 -> Meta de la oportunidad de mejora | C8: Grado de avance del proyecto o acción global | D8: Monitoreo al Plan de Mejoramiento | F8: Seguimiento al plan de mejoramiento
D9: Actividades realizadas para el cumplimineto del proyecto o acción global | E9: Medios de verificación | F9: Verificación (Descripción y evidencias) | G9: Observaciones
A10: ='Plan mejoramiento'!C10 -> Continuar con estrategias para lograr que los resultados de la prueba Saber Pro sean mayores en todas las competencias ai promedio obtenido por los estudiantes del grupo de referencia NBC. | B10: ='Plan mejoramiento'!G10 -> Meta 1. Mantener cinco (5) puntos por encima de los resultados de la prueba Saber Pro del grupo de referencia | C10: 1 | D10: Se hicieron reuniones informativas con los estudiantes, y también simulacros de las pruebas | E10: Evidencia
A11: ='Plan mejoramiento'!C11 -> Mantener la participación en las actividades de Bienestar de un porcentaje significativo de estudiantes del Programa en cada periodo, dada la importancia declarada por la institución, en el desarrollo integral y en la permanencia. | B11: ='Plan mejoramiento'!G11 -> Meta 2a.2b, 2c Incrementar al 60% la participación de la comunidad del programa en actividades de bienestar institucional | D11: Los datos entregados por bienestar no especifican el porcentaje de estudiantes, si no el número de personas que atienden estas actividades. No se entregó el registro de participación en algunas actividades. | E11: Evidencia
A12: ='Plan mejoramiento'!C12 -> Bajo porcentaje de profesores y administrativos en actividades de Bienestar
A14: ='Plan mejoramiento'!C14 -> El número de profesores no es suficiente para las necesidades del programa en relación con el número de estudiantes. | B14: ='Plan mejoramiento'!G14 -> Meta 3. Desarrollar una (1) convocatoria de planta docente | D14: Esta meta no corresponde a este año | E14: Evidencia
A15: ='Plan mejoramiento'!C15 -> Los tiempos de dedicación a las funciones misionales no cumplen con lo establecido en los indicadores del programa. | B15: ='Plan mejoramiento'!G15 -> Meta 4. Incrementar al 25% la asignación de tiempos de los docentes TC a la investigación | C15: 0.71 | D15: La meta para el 2024 es 10%, se alcanzó 7.1% | E15: Evidencia
B16: ='Plan mejoramiento'!G16 -> Meta 5. Incrementar al 20% la asignación de tiempos de los docentes TC a la Proyección Social | C16: 0.1 | D16: La meta para el 2024 es 8%, se alcanzó 1% | E16: Evidencia
A17: ='Plan mejoramiento'!C17 -> Continuar con estrategias para aumentar el material de apoyo docente, su aplicación, y difusión. | B17: ='Plan mejoramiento'!G17 -> Meta 6. Desarrollar una (1) estrategia anual para fomentar la productividad y el material de apoyo docente | C17: 0 | D17: Se planea implementar en el 2025-I | E17: Evidencia
A18: ='Plan mejoramiento'!C18 -> El número de productos derivados de la participación de profesores, estudiantes y directivos del programa en redes u organismos nacionales e internacionales es bajo. | B18: ='Plan mejoramiento'!G18 -> Meta 7. Incrementar al 30% la participación de los docentes en redes u organismos nacionales e internacionales para generar productos | C18: 0 | D18: No hay medición para calcular el porcentaje. Se planea hacer la primera medición el 2025-I | E18: Evidencia
B19: ='Plan mejoramiento'!G19 -> Meta 8. Desarrollar un (1) producto bienalmente como resultado de la articulación de redes académicas | C19: 0 | E19: Evidencia
A20: ='Plan mejoramiento'!C20 -> Continuar promoviendo la movilidad entrante nacional e internacional y la saliente nacional | B20: ='Plan mejoramiento'!G20 -> Meta 9. Realizar la movilidad de un (1) estudiante extranjero bienalmente | C20: 1 | D20: Dos estudiantes extranjeros estuvieron en el programa. Oreste Lomis de Bélgica y Neyeli Verenice Sobrado Vergara del Perú. Se ha cumplido la meta para el primer bienio | E20: Evidencia
A21: ='Plan mejoramiento'!C21 -> Aumentar la movilidad saliente de estudiantes del Programa en distintas modalidades. Aunque el Programa argumenta la reducción en este indicador, en la pandemia y el paro, es posible complementar estos resultados, estableciendo otras actividades en distintas modalidades con efectos en la visibilidad y la cooperación nacional e internacional. | B21: ='Plan mejoramiento'!G21 -> Meta 10. Lograr que el 20% de estudiantes a partir del V semestre realicen movilidad saliente nacional o internacional anualmente | C21: 0.934 | D21: 12 estudiantes participaron en movilidad saliente. Considerando que para calcular la línea base se consideró un promedio de 80 estudiantes, los que están a partir de quinto semestre, el porcentaje corresponde a 15%. Para el 2024 la meta es 16%. | E21: Evidencia
A22: ='Plan mejoramiento'!C22 -> Persistir en acciones que permitan de manera efectiva continuar disminuyendo la deserción en el Programa. La tasa de deserción anual para 3 periodos entre 2019 y 2021 es superior al promedio nacional para nivel de formación. | B22: ='Plan mejoramiento'!G22 -> Meta 11. Mantener un (1) digito la tasa deserción del programa | D22: No hay datos actualizados para el 2024-2 | E22: Evidencia
A23: ='Plan mejoramiento'!C23 -> Continuar con la estrategia para lograr la graduación en el tiempo aprobado en el registro calificado. La tasa acumulada de graduación del Programa al semestre 13 es del 23.57% inferior al promedio nacional para el profesional universitario. Aunque es mejor con relación al proceso anterior de acreditación, aún hay una Oportunidad de mejora significativa en el comparativo nacional con el promedio del nivel de formación. | B23: ='Plan mejoramiento'!G23 -> Meta 12. Mantener en 12,5 de semestres para la graduación | D23: No hay datos actualizados para el 2024-2 | E23: Evidencia
A24: ='Plan mejoramiento'!C24 -> Continuar con estrategias y apoyos para mejorar la categoría de los grupos de investigación y el reconocimiento de profesores como investigadores. | B24: ='Plan mejoramiento'!G24 -> Meta 13. Lograr que un (1) grupos de investigación suba de categoría | D24: En este periodo no hubo categorización de grupos. | E24: Evidencia
A25: ='Plan mejoramiento'!C25 -> Se requiere incrementar el número de registros de egresados en la base de datos | B25: ='Plan mejoramiento'!G25 -> Meta 14. Aumentar al 45% los registros actualizados de los egresados en la base de datos del Programa | D25: El programa de egresados de la dirección de proyección social no ha enviado información actualizada | E25: Evidencia
A26: ='Plan mejoramiento'!C26 -> Continuar robusteciendo la infraestructura de laboratorios y equipos disponibles para el Programa en las distintas líneas de profundización, tanto para la docencia, coma para la investigación, y cumplir con el plan de mantenimiento y calibración de equipos de laboratorios de manera permanente. | B26: ='Plan mejoramiento'!G26 -> Meta 15. Construir un (1) complejo de laboratorios | D26: La meta no es para este periodo | E26: Evidencia
B27: ='Plan mejoramiento'!G27 -> Meta 16. Ejecutar el 100% del plan de adquisición de equipos de medios educativos para los laboratorios del Sistema de Gestión de Laboratorios. | D27: La meta no es para este periodo | E27: Evidencia
A28: ='Plan mejoramiento'!C28 -> Se requiere fortalecer el seguimiento de la medición de impacto que evidencie el desarrollo de las funciones misionales | B28: ='Plan mejoramiento'!G28 -> Meta 17. Obtener el nivel de cumplimiento mayor o igual al 80% en la medición del impacto | D28: No hay una directriz clara para la medición del impacto | E28: Evidencia

Sheet 2025-1
B1: PROCESO DE GESTIÓN DE LA CALIDAD
B2: PLAN DE MEJORAMIENTO DE PROCESOS DE AUTOEVALUACIÓN
B3: Código: FO-GCL-20 | D3: Versión: 03 | E3: Fecha de aprobación: 14/06/2022 | G3: Página: 2 de 4
A5: Tipo de plan de mejoramiento: | B5: =IF('Plan mejoramiento'!B5="","",'Plan mejoramiento'!B5) -> De programa | D5: =IF('Plan mejoramiento'!E5="","",CONCATENATE('Plan mejoramiento'!D5," ",'Plan mejoramiento'!E5)) -> Programa: Ingeniería Electrónica
A6: ='Plan mejoramiento'!A6 -> Facultad: | B6: ='Plan mejoramiento'!B6 -> Facultad de Ciencias Básicas e Ingeniería | D6: =IF('Plan mejoramiento'!J6="","",CONCATENATE('Plan mejoramiento'!J6," ",#REF!)) -> #REF!
A8: ='Plan mejoramiento'!C8 -> Descripción de la oportunidad de mejora | B8: ='Plan mejoramiento'!G8 -> Meta de la oportunidad de mejora | C8: Grado de avance del proyecto o acción global | D8: Monitoreo al Plan de Mejoramiento | F8: Seguimiento al plan de mejoramiento
D9: Actividades realizadas para el cumplimineto del proyecto o acción global | E9: Medios de verificación | F9: Verificación (Descripción y evidencias) | G9: Observaciones
A10: ='Plan mejoramiento'!C10 -> Continuar con estrategias para lograr que los resultados de la prueba Saber Pro sean mayores en todas las competencias ai promedio obtenido por los estudiantes del grupo de referencia NBC. | B10: ='Plan mejoramiento'!G10 -> Meta 1. Mantener cinco (5) puntos por encima de los resultados de la prueba Saber Pro del grupo de referencia | C10: 1 | D10: Se hicieron reuniones informativas con los estudiantes, y también simulacros de las pruebas. Al momento de realizar este informe, no hay resultados de las pruebas Saber Pro realizadas durante el 2025-I | E10: Evidencia
A11: ='Plan mejoramiento'!C11 -> Mantener la participación en las actividades de Bienestar de un porcentaje significativo de estudiantes del Programa en cada periodo, dada la importancia declarada por la institución, en el desarrollo integral y en la permanencia. | B11: ='Plan mejoramiento'!G11 -> Meta 2a.2b, 2c Incrementar al 60% la participación de la comunidad del programa en actividades de bienestar institucional | C11: 0.786 | D11: Profesores, administrativos y estudiantes se benefician de los servicios y actvidades de bienestar universitario; sin embargo, no ha registro de dichas participaciones para este periodo se hicieron encuestas para recoger dicha información directamente de los beneficiados obteniendo que 100% de los admistrativos participaron en actividades de bienestar, 39.5 % de los profesores, y la totalidad de los estudiantes. lo que da un promedio de 78,6% de alcance de esta meta, considerando que se quiere alcanzar un 60% de participación. | E11: Evidencia
A12: ='Plan mejoramiento'!C12 -> Bajo porcentaje de profesores y administrativos en actividades de Bienestar
A14: ='Plan mejoramiento'!C14 -> El número de profesores no es suficiente para las necesidades del programa en relación con el número de estudiantes. | B14: ='Plan mejoramiento'!G14 -> Meta 3. Desarrollar una (1) convocatoria de planta docente | C14: 0.5 | D14: Se definieron tres perfiles para profesores de planta para el programa. | E14: Evidencia
A15: ='Plan mejoramiento'!C15 -> Los tiempos de dedicación a las funciones misionales no cumplen con lo establecido en los indicadores del programa. | B15: ='Plan mejoramiento'!G15 -> Meta 4. Incrementar al 25% la asignación de tiempos de los docentes TC a la investigación | C15: 0.757 | D15: Para el 2025, la meta es 15% de dedicación a investigación. Durante el 2025-I, los profesores de la escuela de ingeniería que prestan servicios en el programa tuvieron una dedicación de 11,35% a investigación, lo que representa que la meta se ha alcanzado en una 75,7% | E15: Evidencia
A16: ='Plan mejoramiento'!C16 | B16: ='Plan mejoramiento'!G16 -> Meta 5. Incrementar al 20% la asignación de tiempos de los docentes TC a la Proyección Social | C16: 0.8 | D16: Para el 2025, la meta es 12% de dedicación a investigación. Durante el 2025-I, los profesores de la escuela de ingeniería que prestan servicios en el programa tuvieron una dedicación de 9,6% a proyección social, lo que representa que la meta se ha alcanzado en una 80% | E16: Evidencia
A17: ='Plan mejoramiento'!C17 -> Continuar con estrategias para aumentar el material de apoyo docente, su aplicación, y difusión. | B17: ='Plan mejoramiento'!G17 -> Meta 6. Desarrollar una (1) estrategia anual para fomentar la productividad y el material de apoyo docente | C17: 0 | D17: Se recogerá la información durante el intersemestral del 2025 | E17: Evidencia
A18: ='Plan mejoramiento'!C18 -> El número de productos derivados de la participación de profesores, estudiantes y directivos del programa en redes u organismos nacionales e internacionales es bajo. | B18: ='Plan mejoramiento'!G18 -> Meta 7. Incrementar al 30% la participación de los docentes en redes u organismos nacionales e internacionales para generar productos | C18: 1 | D18: Los profesores Javier Martínez, Javier Ricardo Castro y Héctor Iván Reyes trabajaron colaborativamente con profesores de otras universidades. El profesor Javier Martínez trabajó con un profesor de la Universidad Militar en la publicación de artículos, el profesor Javier Ricardo Castro trabajó con profesores de la Universidad de Antioquía en investigación, y el profesor con un profesor del Seneca Polytechnical College en un procyecto COIL. Esto representa el 23% de los 13 profesores de la escuela de ingeniería que prestaron servicios al programa durante el 2025-I. Considerando que para este periodo el porcentaje esperado es 22%, esta meta se cumplió al 100%. | E18: Evidencia
A19: ='Plan mejoramiento'!C19 | B19: ='Plan mejoramiento'!G19 -> Meta 8. Desarrollar un (1) producto bienalmente como resultado de la articulación de redes académicas | C19: 1 | D19: El ingeniero Javier Martínez publicó el artículo "Imitation of the Human Upper Limb by Convolutional Neural Networks" en el journal International Journal of Artificial Intelligence (IJ-AI), en colaboración con el profesor Robinsón Moreno de la Universidad Militar Nueva Granada. La meta para el periodo 2024-2 - 2026-2 está cumplida | E19: Evidencia
A20: ='Plan mejoramiento'!C20 -> Continuar promoviendo la movilidad entrante nacional e internacional y la saliente nacional | B20: ='Plan mejoramiento'!G20 -> Meta 9. Realizar la movilidad de un (1) estudiante extranjero bienalmente | C20: 1 | D20: Dos estudiantes extranjeros estuvieron en el programa. Oreste Lomis de Bélgica y Neyeli Verenice Sobrado Vergara del Perú. Se ha cumplido la meta para el primer bienio | E20: Evidencia
A21: ='Plan mejoramiento'!C21 -> Aumentar la movilidad saliente de estudiantes del Programa en distintas modalidades. Aunque el Programa argumenta la reducción en este indicador, en la pandemia y el paro, es posible complementar estos resultados, estableciendo otras actividades en distintas modalidades con efectos en la visibilidad y la cooperación nacional e internacional. | B21: ='Plan mejoramiento'!G21 -> Meta 10. Lograr que el 20% de estudiantes a partir del V semestre realicen movilidad saliente nacional o internacional anualmente | C21: 1 | D21: 16 estudiantes participaron en movilidad saliente. Considerando que para calcular la línea base se consideró un promedio de 80 estudiantes, los que están a partir de quinto semestre, el porcentaje corresponde a 20%. Para el 2025 la meta es 17%. Por los tanto la meta se cumplió al 100% | E21: Evidencia
A22: ='Plan mejoramiento'!C22 -> Persistir en acciones que permitan de manera efectiva continuar disminuyendo la deserción en el Programa. La tasa de deserción anual para 3 periodos entre 2019 y 2021 es superior al promedio nacional para nivel de formación. | B22: ='Plan mejoramiento'!G22 -> Meta 11. Mantener un (1) digito la tasa deserción del programa | C22: 0 | D22: No hay datos actualizados para el 2025-I | E22: Evidencia
A23: ='Plan mejoramiento'!C23 -> Continuar con la estrategia para lograr la graduación en el tiempo aprobado en el registro calificado. La tasa acumulada de graduación del Programa al semestre 13 es del 23.57% inferior al promedio nacional para el profesional universitario. Aunque es mejor con relación al proceso anterior de acreditación, aún hay una Oportunidad de mejora significativa en el comparativo nacional con el promedio del nivel de formación. | B23: ='Plan mejoramiento'!G23 -> Meta 12. Mantener en 12,5 de semestres para la graduación | C23: 0 | D23: No hay datos actualizados para el 2025-I | E23: Evidencia
A24: ='Plan mejoramiento'!C24 -> Continuar con estrategias y apoyos para mejorar la categoría de los grupos de investigación y el reconocimiento de profesores como investigadores. | B24: ='Plan mejoramiento'!G24 -> Meta 13. Lograr que un (1) grupos de investigación suba de categoría | C24: 1 | D24: El grupo Macrypt subió de categoría B a categoría A, mientras que los demás grupos se mantuvieron en sus categorías | E24: Evidencia
A25: ='Plan mejoramiento'!C25 -> Se requiere incrementar el número de registros de egresados en la base de datos | B25: ='Plan mejoramiento'!G25 -> Meta 14. Aumentar al 45% los registros actualizados de los egresados en la base de datos del Programa | C25: 0 | D25: El programa de egresados de la dirección de proyección social no ha enviado información actualizada | E25: Evidencia
A26: ='Plan mejoramiento'!C26 -> Continuar robusteciendo la infraestructura de laboratorios y equipos disponibles para el Programa en las distintas líneas de profundización, tanto para la docencia, coma para la investigación, y cumplir con el plan de mantenimiento y calibración de equipos de laboratorios de manera permanente. | B26: ='Plan mejoramiento'!G26 -> Meta 15. Construir un (1) complejo de laboratorios | D26: La meta no es para este periodo | E26: Evidencia
A27: ='Plan mejoramiento'!C27 | B27: ='Plan mejoramiento'!G27 -> Meta 16. Ejecutar el 100% del plan de adquisición de equipos de medios educativos para los laboratorios del Sistema de Gestión de Laboratorios. | D27: La meta no es para este periodo | E27: Evidencia
A28: ='Plan mejoramiento'!C28 -> Se requiere fortalecer el seguimiento de la medición de impacto que evidencie el desarrollo de las funciones misionales | B28: ='Plan mejoramiento'!G28 -> Meta 17. Obtener el nivel de cumplimiento mayor o igual al 80% en la medición del impacto | C28: 0 | D28: No hay una directriz clara para la medición del impacto | E28: Evidencia

Sheet 2025-2
B1: PROCESO DE GESTIÓN DE LA CALIDAD
B2: PLAN DE MEJORAMIENTO DE PROCESOS DE AUTOEVALUACIÓN
B3: Código: FO-GCL-20 | D3: Versión: 03 | E3: Fecha de aprobación: 14/06/2022 | G3: Página: 2 de 4
A5: Tipo de plan de mejoramiento: | B5: =IF('Plan mejoramiento'!B5="","",'Plan mejoramiento'!B5) -> De programa | D5: =IF('Plan mejoramiento'!E5="","",CONCATENATE('Plan mejoramiento'!D5," ",'Plan mejoramiento'!E5)) -> Programa: Ingeniería Electrónica
A6: ='Plan mejoramiento'!A6 -> Facultad: | B6: ='Plan mejoramiento'!B6 -> Facultad de Ciencias Básicas e Ingeniería | D6: =IF('Plan mejoramiento'!J6="","",CONCATENATE('Plan mejoramiento'!J6," ",#REF!)) -> #REF!
A8: ='Plan mejoramiento'!C8 -> Descripción de la oportunidad de mejora | B8: ='Plan mejoramiento'!G8 -> Meta de la oportunidad de mejora | C8: Grado de avance del proyecto o acción global | D8: Monitoreo al Plan de Mejoramiento | F8: Seguimiento al plan de mejoramiento
D9: Actividades realizadas para el cumplimineto del proyecto o acción global | E9: Medios de verificación | F9: Verificación (Descripción y evidencias) | G9: Observaciones
A10: ='Plan mejoramiento'!C10 -> Continuar con estrategias para lograr que los resultados de la prueba Saber Pro sean mayores en todas las competencias ai promedio obtenido por los estudiantes del grupo de referencia NBC. | B10: ='Plan mejoramiento'!G10 -> Meta 1. Mantener cinco (5) puntos por encima de los resultados de la prueba Saber Pro del grupo de referencia | C10: 1 | D10: Se analizaron los resultados de las pruebas Saber Pro para identificar las principales falencias, las cuales fueron socializadas con los docentes con el fin de fortalecer las competencias evaluadas desde las asignaturas. Asimismo, se realizaron simulacros como estrategia de preparación para los estudiantes. Estas acciones fueron presentadas y discutidas en el Comité de Programa | E10: ACTA DE COMITÉ 020 DE 2025
A11: ='Plan mejoramiento'!C11 -> Mantener la participación en las actividades de Bienestar de un porcentaje significativo de estudiantes del Programa en cada periodo, dada la importancia declarada por la institución, en el desarrollo integral y en la permanencia. | B11: ='Plan mejoramiento'!G11 -> Meta 2a.2b, 2c Incrementar al 60% la participación de la comunidad del programa en actividades de bienestar institucional | C11: 0.786 | D11: Los profesores, administrativos y estudiantes se benefician de las actividades y servicios ofrecidos por Bienestar Universitario. Sin embargo, la información suministrada para el periodo no incluye un registro detallado de la participación de los diferentes estamentos, sino únicamente el número de personas atendidas en las actividades. Ante esta situación, se solicitaron los documentos a la entidad encargada. | E11: CARPETA DRIVE
A12: ='Plan mejoramiento'!C12 -> Bajo porcentaje de profesores y administrativos en actividades de Bienestar
A14: ='Plan mejoramiento'!C14 -> El número de profesores no es suficiente para las necesidades del programa en relación con el número de estudiantes. | B14: ='Plan mejoramiento'!G14 -> Meta 3. Desarrollar una (1) convocatoria de planta docente | C14: 0.8 | D14: Durante el periodo 2025-2, la Universidad de los Llanos expidió la resolución que autorizó el concurso público de méritos para la provisión de cargos docentes de carrera y realizó la distribución de las plazas entre las facultades, asignando cuatro (4) a la Facultad de Ciencias Básicas e Ingeniería. Al cierre del periodo, el proceso se encontraba en la etapa previa al concurso, por lo que la selección y vinculación de los docentes quedó prevista para el periodo académico 2026-1. | E14: CARPETA DRIVE
A15: ='Plan mejoramiento'!C15 -> Los tiempos de dedicación a las funciones misionales no cumplen con lo establecido en los indicadores del programa. | B15: ='Plan mejoramiento'!G15 -> Meta 4. Incrementar al 25% la asignación de tiempos de los docentes TC a la investigación | C15: 1 | D15: Para el 2025, la meta es 15% de dedicación a investigación. Durante el 2025-2, los profesores de la escuela de ingeniería que prestan servicios en el programa tuvieron una dedicación de 26,67% a investigación, lo que representa que la meta se ha alcanzado en un 100% | E15: CARPETA DRIVE
A16: ='Plan mejoramiento'!C16 | B16: ='Plan mejoramiento'!G16 -> Meta 5. Incrementar al 20% la asignación de tiempos de los docentes TC a la Proyección Social | C16: 0.8 | D16: Para el 2025, la meta es 12% de dedicación a investigación. Durante el 2025-2, los profesores de la escuela de ingeniería que prestan servicios en el programa tuvieron una dedicación de 26,67% a proyección social, lo que representa que la meta se ha alcanzado en una 100% | E16: CARPETA DRIVE
A17: ='Plan mejoramiento'!C17 -> Continuar con estrategias para aumentar el material de apoyo docente, su aplicación, y difusión. | B17: ='Plan mejoramiento'!G17 -> Meta 6. Desarrollar una (1) estrategia anual para fomentar la productividad y el material de apoyo docente | C17: 0 | D17: Se recogerá la información durante el intersemestral del 2026-1 | E17: CARPETA DRIVE
A18: ='Plan mejoramiento'!C18 -> El número de productos derivados de la participación de profesores, estudiantes y directivos del programa en redes u organismos nacionales e internacionales es bajo. | B18: ='Plan mejoramiento'!G18 -> Meta 7. Incrementar al 30% la participación de los docentes en redes u organismos nacionales e internacionales para generar productos | C18: 0.11 | D18: La docente Lauren Gineth Isaza trabajó colaborativamente con profesores de otro programas de la universidad. Esto representa el 11,11% de los 9 profesores de la escuela de ingeniería que prestaron servicios al programa durante el 2025-II. | E18: CARPETA DRIVE
A19: ='Plan mejoramiento'!C19 | B19: ='Plan mejoramiento'!G19 -> Meta 8. Desarrollar un (1) producto bienalmente como resultado de la articulación de redes académicas | C19: 1 | D19: El docente Javier Ricardo Castro trabajó colaborativamente con profesores de otras universidades. El profesor Javier Ricardo Castro trabajó con profesores de la Universidad de Antioquía en investigación. Esto representa el 33% de los 3 profesores de la escuela de ingeniería que prestaron servicios al programa durante el 2025-II. Considerando que para este periodo el porcentaje esperado es 22%, esta meta se cumplió al 100%. | E19: CARPETA DRIVE
A20: ='Plan mejoramiento'!C20 -> Continuar promoviendo la movilidad entrante nacional e internacional y la saliente nacional | B20: ='Plan mejoramiento'!G20 -> Meta 9. Realizar la movilidad de un (1) estudiante extranjero bienalmente | C20: 0 | D20: El estudiante entrante no cumplió con toda la documentacion solicitada. | E20: CARPETA DRIVE
A21: ='Plan mejoramiento'!C21 -> Aumentar la movilidad saliente de estudiantes del Programa en distintas modalidades. Aunque el Programa argumenta la reducción en este indicador, en la pandemia y el paro, es posible complementar estos resultados, estableciendo otras actividades en distintas modalidades con efectos en la visibilidad y la cooperación nacional e internacional. | B21: ='Plan mejoramiento'!G21 -> Meta 10. Lograr que el 20% de estudiantes a partir del V semestre realicen movilidad saliente nacional o internacional anualmente | C21: 0.0021 | D21: 1 estudiante participó en movilidad saliente. Considerando que para calcular la línea base se consideró un promedio de 80 estudiantes, los que están a partir de quinto semestre, el porcentaje corresponde a 1,25%. Para el 2025 la meta es 17%. Por los tanto la meta no se cumplió | E21: CARPETA DRIVE
A22: ='Plan mejoramiento'!C22 -> Persistir en acciones que permitan de manera efectiva continuar disminuyendo la deserción en el Programa. La tasa de deserción anual para 3 periodos entre 2019 y 2021 es superior al promedio nacional para nivel de formación. | B22: ='Plan mejoramiento'!G22 -> Meta 11. Mantener un (1) digito la tasa deserción del programa | C22: 0.9208 | D22: Los matriculados para el 2025-2 fueron en total 359 estudiantes y en este periodo se tuvo una desercion de 39 estudiantes lo que indica un 10,86%. Esta meta no se cumplió, pero bajo significativamente. Es necesario implementar acciones de mejora para alcanzar el objetivo esperado | E22: CARPETA DRIVE
A23: ='Plan mejoramiento'!C23 -> Continuar con la estrategia para lograr la graduación en el tiempo aprobado en el registro calificado. La tasa acumulada de graduación del Programa al semestre 13 es del 23.57% inferior al promedio nacional para el profesional universitario. Aunque es mejor con relación al proceso anterior de acreditación, aún hay una Oportunidad de mejora significativa en el comparativo nacional con el promedio del nivel de formación. | B23: ='Plan mejoramiento'!G23 -> Meta 12. Mantener en 12,5 de semestres para la graduación | C23: 0 | D23: No hay datos actualizados para el 2025-2 | E23: CARPETA DRIVE
A24: ='Plan mejoramiento'!C24 -> Continuar con estrategias y apoyos para mejorar la categoría de los grupos de investigación y el reconocimiento de profesores como investigadores. | B24: ='Plan mejoramiento'!G24 -> Meta 13. Lograr que un (1) grupos de investigación suba de categoría | C24: 1 | D24: El grupo Macrypt subió de categoría B a categoría A, mientras que los demás grupos se mantuvieron en sus categorías | E24: CARPETA DRIVE
A25: ='Plan mejoramiento'!C25 -> Se requiere incrementar el número de registros de egresados en la base de datos | B25: ='Plan mejoramiento'!G25 -> Meta 14. Aumentar al 45% los registros actualizados de los egresados en la base de datos del Programa | C25: 0 | D25: El programa de egresados de la dirección de proyección social no ha enviado información actualizada | E25: CARPETA DRIVE
A26: ='Plan mejoramiento'!C26 -> Continuar robusteciendo la infraestructura de laboratorios y equipos disponibles para el Programa en las distintas líneas de profundización, tanto para la docencia, coma para la investigación, y cumplir con el plan de mantenimiento y calibración de equipos de laboratorios de manera permanente. | B26: ='Plan mejoramiento'!G26 -> Meta 15. Construir un (1) complejo de laboratorios | D26: La meta no es para este periodo | E26: CARPETA DRIVE
A27: ='Plan mejoramiento'!C27 | B27: ='Plan mejoramiento'!G27 -> Meta 16. Ejecutar el 100% del plan de adquisición de equipos de medios educativos para los laboratorios del Sistema de Gestión de Laboratorios. | D27: La meta no es para este periodo | E27: CARPETA DRIVE
A28: ='Plan mejoramiento'!C28 -> Se requiere fortalecer el seguimiento de la medición de impacto que evidencie el desarrollo de las funciones misionales | B28: ='Plan mejoramiento'!G28 -> Meta 17. Obtener el nivel de cumplimiento mayor o igual al 80% en la medición del impacto | C28: 0 | D28: No hay una directriz clara para la medición del impacto | E28: CARPETA DRIVE

Sheet 2026-1
B1: PROCESO DE GESTIÓN DE LA CALIDAD
B2: PLAN DE MEJORAMIENTO DE PROCESOS DE AUTOEVALUACIÓN
B3: Código: FO-GCL-20 | D3: Versión: 03 | E3: Fecha de aprobación: 14/06/2022 | G3: Página: 2 de 4
A5: Tipo de plan de mejoramiento: | B5: =IF('Plan mejoramiento'!B5="","",'Plan mejoramiento'!B5) -> De programa | D5: =IF('Plan mejoramiento'!E5="","",CONCATENATE('Plan mejoramiento'!D5," ",'Plan mejoramiento'!E5)) -> Programa: Ingeniería Electrónica
A6: ='Plan mejoramiento'!A6 -> Facultad: | B6: ='Plan mejoramiento'!B6 -> Facultad de Ciencias Básicas e Ingeniería | D6: =IF('Plan mejoramiento'!J6="","",CONCATENATE('Plan mejoramiento'!J6," ",#REF!)) -> #REF!
A8: ='Plan mejoramiento'!C8 -> Descripción de la oportunidad de mejora | B8: ='Plan mejoramiento'!G8 -> Meta de la oportunidad de mejora | C8: Grado de avance del proyecto o acción global | D8: Monitoreo al Plan de Mejoramiento | F8: Seguimiento al plan de mejoramiento
D9: Actividades realizadas para el cumplimineto del proyecto o acción global | E9: Medios de verificación | F9: Verificación (Descripción y evidencias) | G9: Observaciones
A10: ='Plan mejoramiento'!C10 -> Continuar con estrategias para lograr que los resultados de la prueba Saber Pro sean mayores en todas las competencias ai promedio obtenido por los estudiantes del grupo de referencia NBC. | B10: ='Plan mejoramiento'!G10 -> Meta 1. Mantener cinco (5) puntos por encima de los resultados de la prueba Saber Pro del grupo de referencia
A11: ='Plan mejoramiento'!C11 -> Mantener la participación en las actividades de Bienestar de un porcentaje significativo de estudiantes del Programa en cada periodo, dada la importancia declarada por la institución, en el desarrollo integral y en la permanencia. | B11: ='Plan mejoramiento'!G11 -> Meta 2a.2b, 2c Incrementar al 60% la participación de la comunidad del programa en actividades de bienestar institucional
A12: ='Plan mejoramiento'!C12 -> Bajo porcentaje de profesores y administrativos en actividades de Bienestar
A14: ='Plan mejoramiento'!C14 -> El número de profesores no es suficiente para las necesidades del programa en relación con el número de estudiantes. | B14: ='Plan mejoramiento'!G14 -> Meta 3. Desarrollar una (1) convocatoria de planta docente
A15: ='Plan mejoramiento'!C15 -> Los tiempos de dedicación a las funciones misionales no cumplen con lo establecido en los indicadores del programa. | B15: ='Plan mejoramiento'!G15 -> Meta 4. Incrementar al 25% la asignación de tiempos de los docentes TC a la investigación
A16: ='Plan mejoramiento'!C16 | B16: ='Plan mejoramiento'!G16 -> Meta 5. Incrementar al 20% la asignación de tiempos de los docentes TC a la Proyección Social
A17: ='Plan mejoramiento'!C17 -> Continuar con estrategias para aumentar el material de apoyo docente, su aplicación, y difusión. | B17: ='Plan mejoramiento'!G17 -> Meta 6. Desarrollar una (1) estrategia anual para fomentar la productividad y el material de apoyo docente
